nohup: ignoring input
nohup: failed to run command 'python': No such file or directory
nohup: ignoring input
Watching for file changes with StatReloader
Exception in thread django-main-thread:
Traceback (most recent call last):
  File "/home/bboardle/.local/lib/python3.10/site-packages/django/db/backends/base/base.py", line 275, in ensure_connection
    self.connect()
  File "/home/bboardle/.local/lib/python3.10/site-packages/django/utils/asyncio.py", line 26, in inner
    return func(*args, **kwargs)
  File "/home/bboardle/.local/lib/python3.10/site-packages/django/db/backends/base/base.py", line 256, in connect
    self.connection = self.get_new_connection(conn_params)
  File "/home/bboardle/.local/lib/python3.10/site-packages/django/utils/asyncio.py", line 26, in inner
    return func(*args, **kwargs)
  File "/home/bboardle/.local/lib/python3.10/site-packages/django/db/backends/mysql/base.py", line 255, in get_new_connection
    connection = Database.connect(**conn_params)
  File "/home/bboardle/.local/lib/python3.10/site-packages/MySQLdb/__init__.py", line 123, in Connect
    return Connection(*args, **kwargs)
  File "/home/bboardle/.local/lib/python3.10/site-packages/MySQLdb/connections.py", line 185, in __init__
    super().__init__(*args, **kwargs2)
MySQLdb.OperationalError: (2002, "Can't connect to local MySQL server through socket '/var/run/mysqld/mysqld.sock' (2)")

The above exception was the direct cause of the following exception:

Traceback (most recent call last):
  File "/usr/lib/python3.10/threading.py", line 1016, in _bootstrap_inner
    self.run()
  File "/usr/lib/python3.10/threading.py", line 953, in run
    self._target(*self._args, **self._kwargs)
  File "/home/bboardle/.local/lib/python3.10/site-packages/django/utils/autoreload.py", line 64, in wrapper
    fn(*args, **kwargs)
  File "/home/bboardle/.local/lib/python3.10/site-packages/django/core/management/commands/runserver.py", line 136, in inner_run
    self.check_migrations()
  File "/home/bboardle/.local/lib/python3.10/site-packages/django/core/management/base.py", line 574, in check_migrations
    executor = MigrationExecutor(connections[DEFAULT_DB_ALIAS])
  File "/home/bboardle/.local/lib/python3.10/site-packages/django/db/migrations/executor.py", line 18, in __init__
    self.loader = MigrationLoader(self.connection)
  File "/home/bboardle/.local/lib/python3.10/site-packages/django/db/migrations/loader.py", line 58, in __init__
    self.build_graph()
  File "/home/bboardle/.local/lib/python3.10/site-packages/django/db/migrations/loader.py", line 235, in build_graph
    self.applied_migrations = recorder.applied_migrations()
  File "/home/bboardle/.local/lib/python3.10/site-packages/django/db/migrations/recorder.py", line 89, in applied_migrations
    if self.has_table():
  File "/home/bboardle/.local/lib/python3.10/site-packages/django/db/migrations/recorder.py", line 63, in has_table
    with self.connection.cursor() as cursor:
  File "/home/bboardle/.local/lib/python3.10/site-packages/django/utils/asyncio.py", line 26, in inner
    return func(*args, **kwargs)
  File "/home/bboardle/.local/lib/python3.10/site-packages/django/db/backends/base/base.py", line 316, in cursor
    return self._cursor()
  File "/home/bboardle/.local/lib/python3.10/site-packages/django/db/backends/base/base.py", line 292, in _cursor
    self.ensure_connection()
  File "/home/bboardle/.local/lib/python3.10/site-packages/django/utils/asyncio.py", line 26, in inner
    return func(*args, **kwargs)
  File "/home/bboardle/.local/lib/python3.10/site-packages/django/db/backends/base/base.py", line 274, in ensure_connection
    with self.wrap_database_errors:
  File "/home/bboardle/.local/lib/python3.10/site-packages/django/db/utils.py", line 91, in __exit__
    raise dj_exc_value.with_traceback(traceback) from exc_value
  File "/home/bboardle/.local/lib/python3.10/site-packages/django/db/backends/base/base.py", line 275, in ensure_connection
    self.connect()
  File "/home/bboardle/.local/lib/python3.10/site-packages/django/utils/asyncio.py", line 26, in inner
    return func(*args, **kwargs)
  File "/home/bboardle/.local/lib/python3.10/site-packages/django/db/backends/base/base.py", line 256, in connect
    self.connection = self.get_new_connection(conn_params)
  File "/home/bboardle/.local/lib/python3.10/site-packages/django/utils/asyncio.py", line 26, in inner
    return func(*args, **kwargs)
  File "/home/bboardle/.local/lib/python3.10/site-packages/django/db/backends/mysql/base.py", line 255, in get_new_connection
    connection = Database.connect(**conn_params)
  File "/home/bboardle/.local/lib/python3.10/site-packages/MySQLdb/__init__.py", line 123, in Connect
    return Connection(*args, **kwargs)
  File "/home/bboardle/.local/lib/python3.10/site-packages/MySQLdb/connections.py", line 185, in __init__
    super().__init__(*args, **kwargs2)
django.db.utils.OperationalError: (2002, "Can't connect to local MySQL server through socket '/var/run/mysqld/mysqld.sock' (2)")
